<?xml version="1.0" ?>
<!-- =================================================================================== -->
<!-- |    This document was autogenerated by xacro from robot_6_joint.urdf.xacro       | -->
<!-- |    EDITING THIS FILE BY HAND IS NOT RECOMMENDED                                 | -->
<!-- =================================================================================== -->
<robot name="robot">
  <material name="white">
    <color rgba="1 1 1 1"/>
  </material>
  <material name="black">
    <color rgba="0 0 0 1"/>
  </material>
  <material name="orange">
    <color rgba="1 0.3 0.1 1"/>
  </material>
  <material name="red">
    <color rgba="1 0 0 1"/>
  </material>
  <material name="green">
    <color rgba="0 1 0 1"/>
  </material>
  <material name="blue">
    <color rgba="0 0 1 1"/>
  </material>
  <material name="cyan">
    <color rgba="0 1 1 1"/>
  </material>
  <material name="yellow">
    <color rgba="1 1 0 1"/>
  </material>
  <material name="magenta">
    <color rgba="1 0 1 1"/>
  </material>
  <!-- Specify some standard inertial calculations https://en.wikipedia.org/wiki/List_of_moments_of_inertia -->
  <!-- These make use of xacro's mathematical functionality -->
  <!-- base link-->
  <link name="base_link">

    </link>
  <!--main base link-->
  <!--main base plate-->
  <link name="main_base_square">
    <visual>
      <origin xyz="0.21 0 0"/>
      <geometry>
        <box size="0.5 0.4 0.1"/>
      </geometry>
      <material name="white"/>
    </visual>
    <collision>
      <origin xyz="0.21 0 0"/>
      <geometry>
        <box size="0.5 0.4 0.1"/>
      </geometry>
    </collision>
    <inertial>
      <origin rpy="0 0 0" xyz="0.21 0 0"/>
      <mass value="2"/>
      <inertia ixx="0.02833333333333334" ixy="0.0" ixz="0.0" iyy="0.043333333333333335" iyz="0.0" izz="0.06833333333333333"/>
    </inertial>
  </link>
  <gazebo reference="main_base_square">
    <material>Gazebo/White</material>
  </gazebo>
  <!--joint between base plate and lidar-->
  <joint name="base_lidar_joint" type="fixed">
    <parent link="main_base_square"/>
    <child link="lidar"/>
    <origin rpy="0 0 0" xyz="0.21 0 0.05"/>
  </joint>
  <!--lidar link-->
  <link name="lidar">
    <visual>
      <origin xyz="0 0 0.025"/>
      <geometry>
        <cylinder length="0.04" radius="0.05"/>
      </geometry>
      <material name="black"/>
    </visual>
    <collision>
      <origin xyz="0 0 0.025"/>
      <geometry>
        <cylinder length="0.04" radius="0.05"/>
      </geometry>
    </collision>
    <inertial>
      <origin rpy="0 0 0" xyz="0 0 0.025"/>
      <mass value="2"/>
      <inertia ixx="0.001516666666666667" ixy="0.0" ixz="0.0" iyy="0.001516666666666667" iyz="0.0" izz="0.0025000000000000005"/>
    </inertial>
  </link>
  <gazebo reference="lidar">
    <material>Gazebo/Black</material>
  </gazebo>
  <!-- base to chasiis-->
  <joint name="base_link_joint" type="fixed">
    <parent link="base_link"/>
    <child link="main_base_square"/>
    <origin xyz="-0.21 0 0"/>
  </joint>
  <!-- leg 1-->
  <link name="leg1_1">
    <visual>
      <origin xyz="0.15 0 0"/>
      <geometry>
        <box size="0.3 0.08 0.05"/>
      </geometry>
      <material name="orange"/>
    </visual>
    <collision>
      <origin xyz="0.15 0 0"/>
      <geometry>
        <box size="0.3 0.08 0.05"/>
      </geometry>
    </collision>
    <inertial>
      <origin rpy="0 0 0" xyz="0.15 0 0"/>
      <mass value="0.3"/>
      <inertia ixx="0.00022250000000000001" ixy="0.0" ixz="0.0" iyy="0.0023125" iyz="0.0" izz="0.00241"/>
    </inertial>
  </link>
  <gazebo reference="leg1_1">
    <material>Gazebo/Orange</material>
  </gazebo>
  <joint name="leg1_joint" type="revolute">
    <parent link="leg1_1"/>
    <child link="leg1_2"/>
    <origin xyz="0.3 0 0"/>
    <limit effort="100" lower="-1.57" upper="1.57" velocity="3"/>
    <axis xyz="0 0 1"/>
  </joint>
  <link name="leg1_2">
    <visual>
      <origin xyz="0.25 0 0"/>
      <geometry>
        <box size="0.5 0.08 0.05"/>
      </geometry>
      <material name="yellow"/>
    </visual>
    <collision>
      <origin xyz="0.25 0 0"/>
      <geometry>
        <box size="0.5 0.08 0.05"/>
      </geometry>
    </collision>
    <inertial>
      <origin rpy="0 0 0" xyz="0.25 0 0"/>
      <mass value="0.5"/>
      <inertia ixx="0.00037083333333333337" ixy="0.0" ixz="0.0" iyy="0.010520833333333333" iyz="0.0" izz="0.010683333333333333"/>
    </inertial>
  </link>
  <gazebo reference="leg1_2">
    <material>Gazebo/Yellow</material>
  </gazebo>
  <!-- leg 2-->
  <link name="leg2_1">
    <visual>
      <origin xyz="0.15 0 0"/>
      <geometry>
        <box size="0.3 0.08 0.05"/>
      </geometry>
      <material name="orange"/>
    </visual>
    <collision>
      <origin xyz="0.15 0 0"/>
      <geometry>
        <box size="0.3 0.08 0.05"/>
      </geometry>
    </collision>
    <inertial>
      <origin rpy="0 0 0" xyz="0.15 0 0"/>
      <mass value="0.3"/>
      <inertia ixx="0.00022250000000000001" ixy="0.0" ixz="0.0" iyy="0.0023125" iyz="0.0" izz="0.00241"/>
    </inertial>
  </link>
  <gazebo reference="leg2_1">
    <material>Gazebo/Orange</material>
  </gazebo>
  <joint name="leg2_joint" type="revolute">
    <parent link="leg2_1"/>
    <child link="leg2_2"/>
    <origin xyz="0.3 0 0"/>
    <limit effort="100" lower="-1.57" upper="1.57" velocity="3"/>
    <axis xyz="0 0 1"/>
  </joint>
  <link name="leg2_2">
    <visual>
      <origin xyz="0.25 0 0"/>
      <geometry>
        <box size="0.5 0.08 0.05"/>
      </geometry>
      <material name="yellow"/>
    </visual>
    <collision>
      <origin xyz="0.25 0 0"/>
      <geometry>
        <box size="0.5 0.08 0.05"/>
      </geometry>
    </collision>
    <inertial>
      <origin rpy="0 0 0" xyz="0.25 0 0"/>
      <mass value="0.5"/>
      <inertia ixx="0.00037083333333333337" ixy="0.0" ixz="0.0" iyy="0.010520833333333333" iyz="0.0" izz="0.010683333333333333"/>
    </inertial>
  </link>
  <gazebo reference="leg2_2">
    <material>Gazebo/Yellow</material>
  </gazebo>
  <!-- leg 3-->
  <link name="leg3_1">
    <visual>
      <origin xyz="0.15 0 0"/>
      <geometry>
        <box size="0.3 0.08 0.05"/>
      </geometry>
      <material name="orange"/>
    </visual>
    <collision>
      <origin xyz="0.15 0 0"/>
      <geometry>
        <box size="0.3 0.08 0.05"/>
      </geometry>
    </collision>
    <inertial>
      <origin rpy="0 0 0" xyz="0.15 0 0"/>
      <mass value="0.3"/>
      <inertia ixx="0.00022250000000000001" ixy="0.0" ixz="0.0" iyy="0.0023125" iyz="0.0" izz="0.00241"/>
    </inertial>
  </link>
  <gazebo reference="leg3_1">
    <material>Gazebo/Orange</material>
  </gazebo>
  <joint name="leg3_joint" type="revolute">
    <parent link="leg3_1"/>
    <child link="leg3_2"/>
    <origin xyz="0.3 0 0"/>
    <limit effort="100" lower="-1.57" upper="1.57" velocity="3"/>
    <axis xyz="0 0 1"/>
  </joint>
  <link name="leg3_2">
    <visual>
      <origin xyz="0.25 0 0"/>
      <geometry>
        <box size="0.5 0.08 0.05"/>
      </geometry>
      <material name="yellow"/>
    </visual>
    <collision>
      <origin xyz="0.25 0 0"/>
      <geometry>
        <box size="0.5 0.08 0.05"/>
      </geometry>
    </collision>
    <inertial>
      <origin rpy="0 0 0" xyz="0.25 0 0"/>
      <mass value="0.5"/>
      <inertia ixx="0.00037083333333333337" ixy="0.0" ixz="0.0" iyy="0.010520833333333333" iyz="0.0" izz="0.010683333333333333"/>
    </inertial>
  </link>
  <gazebo reference="leg3_2">
    <material>Gazebo/Yellow</material>
  </gazebo>
  <!-- base to leg 1-->
  <joint name="base_leg1_joint" type="revolute">
    <parent link="main_base_square"/>
    <child link="leg1_1"/>
    <origin rpy="-1.5707963267948966 0 0" xyz="0.46 0 0"/>
    <limit effort="10" lower="0" upper="3.14" velocity="3"/>
    <axis xyz="0 0 1"/>
  </joint>
  <!-- base to leg 2-->
  <joint name="base_leg2_joint" type="revolute">
    <parent link="main_base_square"/>
    <child link="leg2_1"/>
    <origin rpy="-1.5707963267948966 0 0" xyz="0 0.225 0"/>
    <limit effort="10" lower="0" upper="3.14" velocity="3"/>
    <axis xyz="0 0 1"/>
  </joint>
  <!-- base to leg 3-->
  <joint name="base_leg3_joint" type="revolute">
    <parent link="main_base_square"/>
    <child link="leg3_1"/>
    <origin rpy="1.5707963267948966 0 0" xyz="0 -0.225 0"/>
    <limit effort="10" lower="0" upper="3.14" velocity="3"/>
    <axis xyz="0 0 -1"/>
  </joint>
</robot>

